<?xml version="1.0" encoding="utf-8"?>
<!-- This URDF was automatically created by SolidWorks to URDF Exporter! Originally created by Stephen Brawner (brawner@gmail.com) 
     Commit Version: 1.6.0-4-g7f85cfe  Build Version: 1.6.7995.38578
     For more information, please see http://wiki.ros.org/sw_urdf_exporter -->

<robot name="myrobot" xmlns:xacro="http://www.ros.org/wiki/xacro">

<xacro:include filename="$(find myrobot)/urdf/diffrobot.gazebo"/>

<link name="base_footprint">  
</link>

<joint name="base_footprint_joint" type="fixed">
      <origin
        xyz="0.0 0.0 0.0"
        rpy="0 0 0" />
    <parent link ="base_footprint"/>
    <child link ="base_link"/>   
</joint>

<link name="base_link">
    <inertial>
        <origin xyz="0.0 0.0 0.0" rpy="0.0 0.0 0.0"/>
        <mass value="8.0"/>
        <inertia ixx="0.0" ixy="0.0" ixz="0.0" iyy="0.0" iyz="0.0" izz="0.0"/>
    </inertial>
    <visual name="base_link_visual">
        <geometry>
           <cylinder radius="0.5" length="0.008"/>
        </geometry>
        <material name="">
            <color rgba="1.0 0.0 0.0 1.0"/>
            <texture filename=""/>
        </material>
    </visual>
    <collision>
        <origin xyz="0.0 0.0 0.0" rpy="0.0 0.0 0.0"/>
        <geometry>
           <cylinder radius="0.5" length="0.008"/>
        </geometry>
    </collision>
</link>





<link name="left_wheel">
    <inertial>
        <origin xyz="0.0 0.0 0.0" rpy="0.0 0.0 0.0"/>
        <mass value="1.0"/>
        <inertia ixx="1.0" ixy="0.0" ixz="0.0" iyy="1.0" iyz="0.0" izz="1.0"/>
    </inertial>
    <visual name="left_wheel_visual">
        <origin xyz="0.0 0.0 0.0" rpy="0.0 0.0 0.0"/>
        <geometry>
            <cylinder radius="0.085" length="0.032"/>
        </geometry>
        <material name="">
            <color rgba="0.0 0.0 1.0 1.0"/>
            <texture filename=""/>
        </material>
    </visual>
    <collision>
        <origin xyz="0.0 0.0 0.0" rpy="0.0 0.0 0.0"/>
        <geometry>
            <cylinder radius="0.085" length="0.032"/>
        </geometry>
    </collision>
</link>


<joint name="left_wheel_joint" type="continuous">
    <origin xyz="0.0 0.43 0.025" rpy="0.0 1.5707 1.5707"/>
    <parent link="base_link"/>
    <child link="left_wheel"/>
    <axis xyz="0.0 0.0 1.0"/>
    <limit lower="0.0" upper="0.0" effort="0.0" velocity="0.0"/>
</joint>


<link name="right_wheel">
    <inertial>
        <origin xyz="0.0 0.0 0.0" rpy="0.0 0.0 0.0"/>
        <mass value="1.0"/>
        <inertia ixx="1.0" ixy="0.0" ixz="0.0" iyy="1.0" iyz="0.0" izz="1.0"/>
    </inertial>
    <visual name="right_wheel_visual">
        <origin xyz="0.0 0.0 0.0" rpy="0.0 0.0 0.0"/>
        <geometry>
            <cylinder radius="0.085" length="0.032"/>
        </geometry>
        <material name="">
            <color rgba="0.0 0.0 1.0 1.0"/>
            <texture filename=""/>
        </material>
    </visual>
    <collision>
        <origin xyz="0.0 0.0 0.0" rpy="0.0 0.0 0.0"/>
        <geometry>
            <cylinder radius="0.085" length="0.032"/>
        </geometry>
    </collision>
</link>


<joint name="right_wheel_joint" type="continuous">
    <origin xyz="0.0 -0.43 0.025" rpy="0.0 1.5707 1.5707"/>
    <parent link="base_link"/>
    <child link="right_wheel"/>
    <axis xyz="0.0 0.0 1.0"/>
    <limit lower="0.0" upper="0.0" effort="0.0" velocity="0.0"/>
</joint>

<link name="front_caster">
    <inertial>
        <origin xyz="0.0 0.0 0.0" rpy="0.0 0.0 0.0"/>
        <mass value="0.0"/>
        <inertia ixx="0.0" ixy="0.0" ixz="0.0" iyy="0.0" iyz="0.0" izz="0.0"/>
    </inertial>
    <visual name="front_caster_visual">
        <origin xyz="0.0 0.0 0.0" rpy="0.0 0.0 0.0"/>
        <geometry>
             <sphere radius="0.038"/>
        </geometry>
        <material name="">
            <color rgba="1.0 1.0 0.0 1.0"/>
        </material>
    </visual>
    <collision>
        <origin xyz="0.0 0.0 0.0" rpy="0.0 0.0 0.0"/>
        <geometry>
            <sphere radius="0.038"/>
        </geometry>
    </collision>
</link>

<joint name="front_caster_joint" type="fixed">
    <origin xyz="0.35 0.0 -0.0175" rpy="0.0 1.5707 1.5707"/>
    <parent link="base_link"/>
    <child link="front_caster"/>
    <axis xyz="0.0 0.0 0.0"/>
    <limit lower="0.0" upper="0.0" effort="0.0" velocity="0.0"/>
</joint>


<link name="back_caster">
    <inertial>
        <origin xyz="0.0 0.0 0.0" rpy="0.0 0.0 0.0"/>
        <mass value="0.0"/>
        <inertia ixx="0.0" ixy="0.0" ixz="0.0" iyy="0.0" iyz="0.0" izz="0.0"/>
    </inertial>
    <visual name="back_caster_visual">
        <origin xyz="0.0 0.0 0.0" rpy="0.0 0.0 0.0"/>
        <geometry>
            <sphere radius="0.038"/>
        </geometry>
        <material name="">
            <color rgba="1.0 1.0 0.0 1.0"/>
        </material>
    </visual>
    <collision>
        <origin xyz="0.0 0.0 0.0" rpy="0.0 0.0 0.0"/>
        <geometry>
            <sphere radius="0.038"/>
        </geometry>
    </collision>
</link>

<joint name="back_caster_joint" type="fixed">
    <origin xyz="-0.35 0.0 -0.0175" rpy="0.0 1.5707 1.5707"/>
    <parent link="base_link"/>
    <child link="back_caster"/>
    <axis xyz="0.0 0.0 0.0"/>
    <limit lower="0.0" upper="0.0" effort="0.0" velocity="0.0"/>
</joint>



   
  
</robot>